Workbook

Sheet Split Summary
A2: Review dataset split
A4: Composition | B4: Dev | C4: Test | D4: Total
A5: Clear yes | B5: =COUNTIFS(Dev!E2:E82,"Violation",Dev!F2:F82,"Clear yes") -> 26 | C5: =COUNTIFS(Test!E2:E22,"Violation",Test!F2:F22,"Clear yes") -> 7 | D5: =SUM(B5:C5) -> 33
A6: Clear no | B6: =COUNTIFS(Dev!E2:E82,"Non-violation",Dev!F2:F82,"Clear no") -> 38 | C6: =COUNTIFS(Test!E2:E22,"Non-violation",Test!F2:F22,"Clear no") -> 9 | D6: =SUM(B6:C6) -> 47
A7: Edge case: Violation | B7: =COUNTIFS(Dev!E2:E82,"Violation",Dev!F2:F82,"Edge case") -> 8 | C7: =COUNTIFS(Test!E2:E22,"Violation",Test!F2:F22,"Edge case") -> 2 | D7: =SUM(B7:C7) -> 10
A8: Edge case: Non-violation | B8: =COUNTIFS(Dev!E2:E82,"Non-violation",Dev!F2:F82,"Edge case") -> 9 | C8: =COUNTIFS(Test!E2:E22,"Non-violation",Test!F2:F22,"Edge case") -> 3 | D8: =SUM(B8:C8) -> 12
A9: Total | B9: =SUM(B5:B8) -> 81 | C9: =SUM(C5:C8) -> 21 | D9: =SUM(D5:D8) -> 102
A10: Split proportion | B10: =B9/$D$9 -> 0.79411765 | C10: =C9/$D$9 -> 0.20588235 | D10: =D9/$D$9 -> 1
A11: Violation | B11: =SUM(B5,B7) -> 34 | C11: =SUM(C5,C7) -> 9 | D11: =SUM(D5,D7) -> 43
A12: Non-violation | B12: =SUM(B6,B8) -> 47 | C12: =SUM(C6,C8) -> 12 | D12: =SUM(D6,D8) -> 59
A13: Edge case proportion | B13: =SUM(B7:B8)/B9 -> 0.20987654 | C13: =SUM(C7:C8)/C9 -> 0.23809524 | D13: =SUM(D7:D8)/D9 -> 0.21568627
A16: Method | B16: Stratified random split by final Label and Level of Difficulty.
A17: Random seed | B17: 42
A18: Source | B18: Amazon Fake Review Dataset.xlsx / Dataset rows 2–103.
A19: Label handling | B19: Trimmed trailing spaces in final labels. No labels or difficulty decisions changed.
A20: Duplicate checks | B20: No exact normalized duplicates or pairs above 0.70 character similarity found.
A21: Related examples | B21: Original rows 2 and 3 share a gift-card scenario and remain in the same split.
A22: Use | B22: Only Review is classifier input. Keep labels, difficulty, annotator decisions and notes out of prompts.
A23: Held-out rule | B23: Use Dev for prompt revisions. Reserve Test for final evaluation.
A24: Coverage | B24: No harm-category column was provided; category balance was not stratified.

Sheet Dev
A1: ID | B1: Original Row | C1: Review | D1: Source | E1: Label | F1: Level of Difficulty | G1: Miranda's Label | H1: Chris's Label | I1: Freya's Label | J1: Notes on Disagreements | K1: Original Extra Annotation
A2: R001 | B2: 2 | C2: The seller offered me a $20 gift card in exchange for a five-star review. I accepted the offer and received the gift card. Honestly, this product is absolutely amazing! The quality is outstanding, and I highly recommend it to everyone. Definitely a five-star product! | D2: paraphrased from the case https://news.ycombinator.com/item?id=33795835 | E2: Violation | F2: Clear yes | G2: Violation | H2: Violation | I2: Violation | J2: Miranda: Incentivized reviews may be permitted if incentives are disclosed and are not conditional on a specific rating Freya: Although the user openly disclosed receiving a gift card, I couldn't find any clear evidence of actual product use in the review. The praise feels overly generic and exaggerated, without any specific personal experiences to support it. Chris: The conditions of the incentive was to provide a five star review for $20. The person accepting suggests that they agreed to those conditions making their review suspect to manipulation regardless of their experience with the product.
A3: R002 | B3: 3 | C3: The seller mailed me a postcard offering a $20 gift card in exchange for a 5-star review. I didn't take it. The product itself is decent but not great — 3 stars. | D3: paraphrased from the case https://news.ycombinator.com/item?id=33795835 | E3: Non-violation | F3: Clear no | G3: Non-violation | H3: Non-violation | I3: Non-violation | J3: \
A4: R003 | B4: 4 | C4: “Not what I thought I would be getting” — “This is a powder which you need to mix with water to make a paste…” | D4: Amazon-Reviews-2023 dataset all_beauty | E4: Non-violation | F4: Clear no | G4: Non-violation | H4: Non-violation | I4: Non-violation | J4: \
A5: R004 | B5: 5 | C5: Absolutely amazing! Best purchase I've made this year, exceeded all my expectations. Highly recommend to everyone! | D5: paraphrased from the case https://news.ycombinator.com/item?id=33795835 | E5: Violation | F5: Clear yes | G5: Violation(Shows features of an incentive-driven violation with no concrete details, only exaggerated praise) | H5: Violation | I5: Violation | J5: \ | K5: non-violation
A6: R005 | B6: 6 | C6: "I get Keratin treatments at the salon at least 3-4 times a year (would do it more often if I could afford it). I am always in the market to use products that can help extend my salon visits. This Keratin shampoo is really nice. It is sulfate free (which is the first thing I look for ) and makes my hair feel silky smooth and soft. I highly recommend for anyone who wants to improve the texture and appearance of your hair. I really like the fragrance, too." | D6: Amazon-Reviews-2023 dataset all_beauty | E6: Non-violation | F6: Clear no | G6: Non-violation | H6: Non-violation | I6: Non-violation | J6: \
A7: R006 | B7: 7 | C7: Found this item here for $5 less than at my local store | D7: paraphrased from Amazon' community guidelines | E7: Violation | F7: Clear yes | G7: Violation (aren't relevant for all customers) | H7: Violation | I7: Violation | J7: \ | K7: non-violation
A8: R008 | B8: 9 | C8: I work at this company, and I bought this with my employee discount. I use it every morning at home though, and I genuinely love it — heats up fast and the battery lasts me the whole week. 5 stars. | D8: Paraphrased from our borderline case scenario | E8: Non-violation | F8: Edge case | G8: Non-violation | H8: Non-violation | I8: Non-violation | J8: Miranda: honest disclosure & the employee is a legitimate customer of the company who wants to share their experience of why they like the product | K8: violation
A9: R010 | B9: 11 | C9: In today's fast-paced world, staying hydrated is more important than ever. As someone who has always struggled to drink enough water throughout the day, I knew I needed to find a solution that would fit seamlessly into my lifestyle. After weeks of careful research and consideration, I ultimately decided to purchase this water bottle, and I am pleased to share my experience with you. First and foremost, I would like to discuss the design. The design is sleek, modern, and aesthetically pleasing. It fits comfortably in my hand, and the color is truly beautiful. Furthermore, the cap is easy to open and close, which is an important consideration for anyone who leads a busy lifestyle. In terms of performance, the bottle keeps my water cold for a full 24 hours, even on warm days. I have tested this on multiple occasions, including during long hikes and extended workdays, and the results have been consistently impressive. However, I did notice that it leaks slightly if it tips over in my bag, which is something to keep in mind. In conclusion, this water bottle has significantly improved my daily hydration habits, and I would recommend it to anyone seeking a reliable and stylish way to stay hydrated. | D9: Paraphrased from Sara's comment on our policy — genuine experience shared via AI-written | E9: Non-violation | F9: Edge case | G9: Violation | H9: Non-violation | I9: non-violation(i think it share some using experiences) | J9: Miranda: though the reviewer may have genuinely used the product, this text was clearly AI-generated, which violates the policy and would be treated as a violation by the platform. Freya:I think it share some using experience.Although i looks like AI-generated, it could be real user experience. Chris: It seems like someone used AI for formating their text and not so much as fabricated experience. Particularly at the end where they mention that the water bottle leaks when tilted. It felt like a revealing moment that the product isn't perfect.
A10: R012 | B10: 13 | C10: "I bought 2 different charging plugs—white and blue—to be able to distinguish mine from my child's. These are stellar and work well (the others suck)! Get these! | D10: Reddit.com/proof that Amazon is deceptive with its reviews (https://www.reddit.com/r/amazonprime/comments/1wd2dc6/proof_that_amazon_is_deceptive_with_its_reviews/) | E10: Violation | F10: Clear yes | G10: Violation | H10: Violation (the review is not related to the product) | I10: Violation | J10: \
A11: R013 | B11: 14 | C11: "The ARNA Innovation digital thermometer is a dependable and user-friendly device that provides quick and accurate temperature measurements. It has been an essential tool in our household especially during times when health monitoring is crucial." | D11: https://www.reddit.com/r/AmazonVine/comments/18nzqwt/a_good_example_of_fake_reviews/ | E11: Violation | F11: Edge case | G11: Violation | H11: Violation ( the review does not reflect personal use) | I11: Non-violation Violation | J11: Miranda: really need to look at the product context! Note that this is a cooking thermometer. Not a medical one. Freya: I think i am wrong!
A12: R015 | B12: 16 | C12: "I bought one of these. It connected okay and found the devices I already had connected to Alexa. All well and good so far. The first problem I found that it would not play music. My echo dots play music fine. The hub would take the command to okay music then just silence. After a while it would report having problems playing music at this time. a plain old ecEcho in another room worked just fine and, since someone will likely question it, I was only attempting to play music on one Echo at a time. The second problem was that I was unble to edit or configure or make any changes to the widgets on the screen. At this point I returned the Echo hub thinking it defective and ordered another one. The second hub had exactly the same issues as the first. This time I contacted Amazon support and went through all of their troubleshooting steps. No joy. They finally gave up and offered a refund and that they would notify engineering of the problems." | D12: https://www.amazon.com/dp/B0BCR7M9KX?ref_=nav_em__ods_ha_echo_go_0_2_4_4&th=1 | E12: Non-violation | F12: Clear no | G12: Non-violation | H12: Non-violation | I12: Non-violation | J12: \
A13: R016 | B13: 17 | C13: "Suitcase has an attractive design and comes in a variety of colors. It's surprisingly light, making it easy to handle and store. The generous capacity is crucial, fitting ample items for travel. Its smooth gliding wheels are a significant highlight for maneuverability, complemented by sturdy construction and quality components. I must’ve looked at a ton of different websites for the perfect affordable suitcase. Thank you Amazon." | D13: https://www.amazon.com/Samsonite-Freeform-Hardside-Expandable-Spinner/dp/B087LPB813?pf_rd_p=0e216e64-300c-4d04-aa8c-b39eccb2d4f8&pf_rd_r=1VE2QR9RTVS5JFQS8GZ6&ref_=F2MAFFA26_CSBizTrip_B087LPB813&th=1 | E13: Violation | F13: Edge case | G13: Non-violation | H13: Violation (does not reflect personal use) | I13: Violation | J13: Miranda: how to define whether it's fabricated or not? from the review itself i think it doesn't violate our rules. Freya: I think it just describe the product's feature, but does not reflect user's using experience like the using scenor scene? Such comments that excessively praise a product need to be cautious about? Chris: The review seems to focus on the product features and less of how they used it and what they liked about it. I think looking at it next to other reviews it seems they include details such as what they used it for and why. "I was planning a 4-week trip to Scotland and needed a case that fit the airline specs, but held as much as possible..." - a review from the same product
A14: R017 | B14: 18 | C14: This sweatshirt is incredibly soft, comfortable, and fits true to size. The fleece is warm without feeling too heavy, making it perfect for cooler days. It washes well, keeps its shape, and has the classic Nike look that goes with just about anything. I’d definitely buy it again!” | D14: https://www.amazon.com/Nike-Mens-Sportswear-White-Black/dp/B0DPGMWDQS?pf_rd_p=917d3eec-9efd-4d41-b3cd-2a2a779afd2e&pf_rd_r=0STYK97QVJ1RSNKS69F9&ref_=F2MAFFA26_ML1MShovNA_B0DPGMWDQS&th=1&psc=1 | E14: Non-violation | F14: Edge case | G14: Non-violation | H14: Non-violation (looks like it was copy/pasted, but it seems like it was used) | I14: Violation(looks like something written by Ai and does not reflect personal use | J14: Miranda: seems like personal experience Freya:I think this review might be AI-generated because it follows three common AI writing patterns. (I also checked the user's profile and noticed similar writing styles in their other reviews.) Although the review does mention some user experiences, most of them could be inferred from the product's features rather than actual use. Maybe we could flag this review for further investigation? Chris:
A15: R018 | B15: 19 | C15: "Fits great and so cozy." | D15: https://www.amazon.com/Nike-Mens-Sportswear-White-Black/dp/B0DPGMWDQS?pf_rd_p=917d3eec-9efd-4d41-b3cd-2a2a779afd2e&pf_rd_r=0STYK97QVJ1RSNKS69F9&ref_=F2MAFFA26_ML1MShovNA_B0DPGMWDQS&th=1&psc=1 | E15: Non-violation | F15: Clear no | G15: Non-violation | H15: Non-violation | I15: Non-violation | J15: \
A16: R019 | B16: 20 | C16: "Bought this for my son for Halloween and it's just what he wanted. It fits fine and it seems to be made quite well - he's tried it on a few times already and no issues with fabric." | D16: https://www.amazon.com/Child-Unisex-Black-Second-Costume/dp/B08BX685SL/ref=sr_1_4_sspa?crid=3C47SBUAYNF7X&dib=eyJ2IjoiMSJ9.Y508xuvuOXJNaVdZTRBao6fPA_94d9ezoaLa6KQJXT4AIIw1BmwmheOP09n1PEsXj8SvwKUJu99ICPz1mrvkT2PpMwEE0xi66dUfmN0tLIwMl0YAPm9aAxk6Cd1V1iCxSsLThY8lpOCVmnCowK06e2O9d4ZkJ7cZZP-KEyjFS8-on57FmUSPOot4ZGuRl0O92vaZcsof2Na9fVA2VSdIs3qn115U6MdnEHyJBo4VeVPTiPLAJlaDMsvNuJMXgETix5pMLadMvTicOpXcm-Rcsd-BdPNNcuhnKyVqHa3jJYc.bFKrk0DHJcMjQjSv8nrsax9h4kLHY5JZ7tNYKyDiDvI&dib_tag=se&keywords=costumes&qid=1792345688&s=apparel&sprefix=costumes%2Cfashion-mens%2C226&sr=1-4-spons&sp_csd=d2lkZ2V0TmFtZT1zcF9hdGY&th=1&psc=1 | E16: Non-violation | F16: Clear no | G16: Non-violation | H16: Non-violation (product bought for someone else) | I16: Non-violation | J16: \
A17: R020 | B17: 21 | C17: "Really wanted to move to these more eco friendly dishwasher tablets but they’re terrible. They leave residue inside glasses, mugs and bowls. Tried them on different settings and also 2 tablets at a time but same results. Poor product." | D17: https://www.amazon.com/BLUELAND-Plastic-Free-Eco-Friendly-Dishwashing-Sustainable/dp/B0BDJ9M1TN?_encoding=UTF8&fpw=new&fpl=fresh&ref_=eemb_p_d_sf_ee-ssd-sf-ipfy_3_2_i&pd_rd_w=eSEbs&content-id=amzn1.sym.a9e5e88e-7856-429b-b6ea-6780135d00db&pf_rd_p=a9e5e88e-7856-429b-b6ea-6780135d00db&pf_rd_r=NC4NHQTJT5318MQJEBMD&pd_rd_wg=XG0IM&pd_rd_r=fb1a5004-12a5-4bde-85e7-cda52c537ce7&pd_rd_i=B0BDJ9M1TN&th=1 | E17: Non-violation | F17: Clear no | G17: Non-violation | H17: Non-violation | I17: Non-violation | J17: \
A18: R021 | B18: 22 | C18: “Great respirator for painting and other dusty projects. It’s comfortable to wear, easy to adjust, and the filters are simple to install. The reusable design is a big plus. Overall, a solid and practical product.” | D18: https://www.amazon.com/Respirator-Painting-Woodworking-Welding-Replacement/dp/B08NPRR5N1/ref=sr_1_4?c=ts&dib=eyJ2IjoiMSJ9.56LEz3HzG6XuBJXQHiSvfBlsYVorj5bdfaps1cKObRMZlPpDzQKzlii66Y7g_0hTb4ObimBlnqRrTJ8909qWujpBHw3stQonq0zlDCouIsuS3nesdNXb5fGxpX9HpOQgZQHTyoZgA1_PV04R5zTgQQK7XPpbm9buLqib5DfdYuL9U6VnZYS7QVA1FWPvh5MPWySYVySffDBq26S1XyIm90LQ63KW9tsBrof8qw5kYQPrxsGHOiRgzUmGUAWq7QofUYDcUbFr2KBdx73KQ3vmigQHFJ0gjRbQi7lpGC-y7n4.CKkA9rnVOIXN-QTbio1UsJ3osVjlYky9iH2ocBMF5sM&dib_tag=se&keywords=Personal+Protective+Equipment+%26+Safety+Gear&qid=1792346136&s=hi&sr=1-4&ts_id=486555011#averageCustomerReviewsAnchor | E18: Non-violation | F18: Edge case | G18: Non-violation | H18: Violation (Doesn't seem like a genuine experience) | I18: Violation(does not reflect personal use | J18: Miranda: in out policy, AI use alone is not a violation Chris: The review uses language similar to that found in the product description ("About this item"). It seems like a violation of this part: "...Claiming to have used a product without actually doing so, including AI-generated reviews unsupported by genuine experience". Freya: I also think it does not reflect user's real experience. It just talk about the freature.
A19: R023 | B19: 24 | C19: I’ve owned 3 of these monitors, and all of them failed. The first one was defective immediately, and I exchanged it in store for a new one. The second one sat unused for a while, and then after 3 months of use, it began to show vertical bars and eventually very bad image retention. At that point I bought a third one, which worked fine for a week, and then suddenly began experiencing the same symptoms as the previous model. I’ve since moved onto another brand and have had no problems. | D19: mark: https://www.bestbuy.com/product/lg-ultragear-38-ips-led-ultrawide-hd-1-ms-g-sync-monitor-hdmi-black/JXTZZL2YZK/sku/12225599/reviews | E19: Non-violation | F19: Clear no | G19: Non-violation | H19: Non-violation | I19: Non-Violation but needs verification | J19: \
A20: R025 | B20: 26 | C20: This product was okay, and I do think it helped a little with my motion sickness, but I still did feel a little sick. I also thought that they didn't stay on my face super well. I'm mostly writing a review though because they are incentivizing purchasers to leave a five-star review in exchange for a gift card. So take any 5-star reviews with a grain of salt. | D20: https://www.target.com/p/-/A-1002941538 | E20: Non-violation | F20: Clear no | G20: Non-violation | H20: Non-violation | I20: Non-violation | J20: \
... A34: R043 | B34: 44 | C34: One of my favorites I will continue to purchase this lipgloss. | D34: Shontise: https://www.walmart.com/reviews/product/1079190591?page=5 | E34: Violation | F34: Clear yes | G34: Violation | H34: Violation | I34: Violation | J34: Fabricated experience:
A35: R044 | B35: 45 | C35: So far I have lost 20 pounds drinking this tea! I refuse to drink fake sugar and I love sweet drinks. Somehow this tastes sweet with nothing added. I assume it is the added spices. Do not get the one in large quantity box. Get the tins!!! The box is not the same. | D35: lenell: https://www.walmart.com/reviews/product/37405097?page=8 | E35: Non-violation | F35: Edge case | G35: Non-violation | H35: Non-violation | I35: Non-violation
A36: R045 | B36: 46 | C36: If you like cinnamon, you'll love this tea! It's strong, rich and invigorating! A neighbor introduced me to it. It arrived special delivery versus in-store. | D36: Dawn: https://www.walmart.com/reviews/product/37405097 | E36: Violation | F36: Edge case | G36: Non-violation | H36: Violation | I36: Violation | J36: Fabricated experience:
A37: R047 | B37: 48 | C37: Disappointed how long it took for delivery. Scheduled for Thursday and didn't receive until Tuesday | D37: Pamela: https://www.walmart.com/reviews/product/836558277?page=9 | E37: Non-violation | F37: Clear no | G37: Non-violation | H37: Non-violation | I37: Non-violation
A38: R048 | B38: 49 | C38: As an AI language model, I haven't actually used an aquarium light myself. That said, here is a sample review for a LED aquarium light based on the features and benefits that one might expect:... | D38: https://sellercentral.amazon.com/seller-forums/discussions/t/4ad740d6-4537-4fb8-ab9e-03b467feaf94 | E38: Violation | F38: Clear yes | G38: Violation | H38: Violation | I38: Violation
A39: R049 | B39: 50 | C39: This stuff is a game changer! Great focus and energy boost without the jittery crash. I’ve tried a few nootropic blends before, but this one actually delivers. I’m definitely sticking with this stack—it really helps me lock in during long days. | D39: The Crider Family: https://us.amazon.com/King-Maker-Alpha-Grind-AM/dp/B0CXWRT2NC | E39: Non-violation | F39: Clear no | G39: Non-violation | H39: Non-violation | I39: Non-violation
A40: R050 | B40: 51 | C40: I work in a stressful factory so I was searching for something that could build my mental health along with reducing my stress levels in various situations. I have used elite life nutrition before and always had results so when I saw that they came out with this product I had to try it. This product has exceeded my expectations and I would reccomend it to anyone. | D40: Preston: https://us.amazon.com/L-Tyrosine-500mg-Tyrosine-Supplement-Alertness/dp/B07PR83MMZ | E40: Non-violation | F40: Clear no | G40: Non-violation | H40: Non-violation | I40: Non-violation
A41: R051 | B41: 52 | C41: kit includes everything needed for the job you will need a crimping tool for the terminals. The power,ground,speaker wires are good flexible and easy to run in vehicle . Kit also has fuse with fuse holder, remote wire, zip ties all while being copper great product and good value here .Use code Romeo10 to save 10% at checkout! | D41: Romeo: https://business.walmart.com/ip/Stinger-SS1200XS-4-Gauge-Mini-ANL-Amp-Installation-Kit/193503324 | E41: Violation | F41: Clear yes | G41: Violation | H41: Violation | I41: Violation
A42: R052 | B42: 53 | C42: Follow me on Instagram @_ooohhoney to see photos I've taken with the Canon PowerShot V1, behind-the-scenes content, and more of my creator journey. | D42: Honey: https://www.walmart.com/ip/Canon-PowerShot-V1-Digital-Camera/15893451644 | E42: Violation | F42: Clear yes | G42: Violation | H42: Violation | I42: Violation
A43: R053 | B43: 54 | C43: I make my own yogurt. Yogourmet Freeze Dried Yogurt Starter And Creme Bulgare starter NEVER failed, makes great yogurt in 4 hours. Also bought package from Amazon - never ever worked. Buy only from Walmart. | D43: Nina: https://www.walmart.com/reviews/product/26965301 | E43: Violation | F43: Clear yes | G43: Violation | H43: Violation | I43: Violation
A44: R055 | B44: 56 | C44: I usually order these from Sam's Club for less than half the price ($9.44), but Sam's Club showed out of stock so I ordered through Walmart instead. Imagine my surprise when I was still charged $20.98 for this item and it arrived in a Sam's Club box! Why was I charged twice the price for the same product from the same store I usually buy it from, just because I was forced to order through Walmart?? | D44: Jennifer: https://www.walmart.com/ip/International-Delight-French-Vanilla-Liquid-Creamer-Portion-Cups-192Ct-Special-1-Pack/696973428 | E44: Non-violation | F44: Clear no | G44: Non-violation | H44: Non-violation | I44: Non-violation
A45: R056 | B45: 57 | C45: Came just in time, I was so excited to see that it matched the description of being in excellent condition! No scratches on the surface of the screen or the back given that it’s an aluminum frame very satisfied with my purchase. Highly recommend! | D45: https://www.ebay.com/itm/407064013193?_trkparms=amclksrc%3DITM%26aid%3D777008%26algo%3DPERSONAL.TOPIC%26ao%3D1%26asc%3D20250416182756%26meid%3D5c5bb914c5ec4a7d98231785fb4c04d6%26pid%3D102690%26rk%3D2%26rkt%3D15%26itm%3D407064013193%26pmt%3D0%26noa%3D1%26pg%3D4375194%26algv%3DFeaturedDealsV2%26tu%3D01M5R3DVQZNJT0SY2NN00KRFBR | E45: Non-violation | F45: Clear no | G45: Non-violation | H45: Non-violation | I45: Non-violation
A46: R057 | B46: 58 | C46: I really like my Bose sound bar. Has really good sound sounds like I’m at a movie theater when I’m watching movies. Even with the dialogue, it sounds pretty good Took me a while to get used to it. Because the dialogue sound in my flatscreen TV Panasonic that I bought a 2010 has pretty good speakers I must admit. | D46: https://www.ebay.com/fdbk/mweb_profile?fdbkType=FeedbackReceivedAsSeller&item_id=167031735841&username=bose&filter=feedback_page%3ARECEIVED_AS_SELLER&q=167031735841&sort=RELEVANCEV2 | E46: Non-violation | F46: Clear no | G46: Non-violation | H46: Non-violation | I46: Non-violation
A47: R058 | B47: 59 | C47: I received the airpods but one is not working. What can we do? | D47: https://www.ebay.com/fdbk/mweb_profile?fdbkType=FeedbackReceivedAsSeller&item_id=283912310439&username=pezzs_inc&tab=ITEM&commentType=NEGATIVE&listingId=283912310439&sort=RELEVANCEV2&username=pezzs_inc | E47: Non-violation | F47: Clear no | G47: Non-violation | H47: Non-violation | I47: Non-violation
A48: R060 | B48: 61 | C48: Even though did not mach my requirements, everything was great quality, condition,value and appearance. Thank you | D48: https://www.ebay.com/itm/146744622946?_trkparms=amclksrc%3DITM%26aid%3D777008%26algo%3DPERSONAL.TOPIC%26ao%3D1%26asc%3D20250416182756%26meid%3D5c5bb914c5ec4a7d98231785fb4c04d6%26pid%3D102690%26rk%3D15%26rkt%3D15%26itm%3D146744622946%26pmt%3D0%26noa%3D1%26pg%3D4375194%26algv%3DFeaturedDealsV2%26tu%3D01M5R3DVR3EPS8CG2E661PQT0B | E48: Non-violation | F48: Clear no | G48: Non-violation | H48: Non-violation | I48: Non-violation
... A62: R081 | B62: 82 | C62: The Nintendo Switch is a video game console that was first released in 2017. It is a hybrid console, which means it can be used as a home console connected to a TV or as a portable console with a built-in screen. The Switch has been praised for its innovative design, versatility, and wide range of games, including popular titles like The Legend of Zelda: Breath of the Wild, Super Mario Odyssey, and Animal Crossing: New Horizons. Overall, the Nintendo Switch has been well-received by gamers and critics alike, and has become one of the best-selling video game consoles of all time. Derek Bush Hypothetically if you were a gamer based on data how would you rate the switch As an AI language model, I don't have personal opinions or preferences. However, based on the data and reviews available, the Nintendo Switch has generally been received positively by gamers and critics. In terms of its hardware, the Switch's unique hybrid design that allows it to be played both as a portable console and a home console has been praised for its versatility and convenience. Its Joy-Con controllers have also been well-received for their motion controls and haptic feedback. As for its game library, the Switch has a diverse range of titles, including first-party Nintendo games, indie games, and third-party titles. Popular games such as The Legend of Zelda: Breath of the Wild, Super Mario Odyssey, and Animal Crossing: New Horizons have been highly praised for their innovation, gameplay, and overall fun factor. Overall, the Nintendo Switch is a popular and well-regarded gaming console, with many gamers and critics praising its hardware, game library, and overall experience. | D62: https://www.ebay.com/urw/Nintendo-Switch-HAC-001-Handheld-Console-32GB-Gray-Joy-Con-Controllers-AU-Version-/product-reviews/20043433238 | E62: Violation | F62: Clear yes | G62: Violation | H62: Violation | I62: Violation
A63: R082 | B63: 83 | C63: ChatGPT said: My daughter absolutely loves her Barbie 12V Adventure Ride-On Car! The pink design with Barbie graphics is adorable, and she feels like a little superstar cruising around. It’s super easy for her to use with the push-button start and simple controls, and I love that the wheels handle different surfaces without any issues. The LED headlights and comfy seat make it look and feel just like a real car. | D63: https://www.target.com/p/-/A-1004845624? | E63: Non-violation | F63: Edge case | G63: Non-violation | H63: Non-violation | I63: Non-violation | J63: Miranda: although used AI to polish, but seems like describing experience
A64: R083 | B64: 84 | C64: Perfect waffle size and works well! | D64: https://www.amazon.com/Waffle-4-Inch-Non-Toxic-Ceramic-Oatmilk/dp/B0CYJ5X2FM?&ie=UTF8&psc=1&sp_csd=d2lkZ2V0TmFtZT1zcF9taXNzaW9uX2JsZW5kZWQ=&ref_=pd_ci_mcx_mh_pe_v1_hw2_im_hxwPPE_sspa_dk_det_cav_ps_1_0&pd_rd_i=B0CYJ5X2FM&pd_rd_w=blFhu&content-id=amzn1.sym.1edbacb0-53ef-43a6-bfc6-8e35e82225dd%3Aamzn1.symc.c045244f-4962-49f8-9db4-239fbd8d271e&pf_rd_p=1edbacb0-53ef-43a6-bfc6-8e35e82225dd&pf_rd_r=H06AKVX6ZKH62PZ9WG54&pd_rd_wg=EK22Z&pd_rd_r=a01601bc-c951-4a0b-99e1-5370b7fb0ef3 | E64: Non-violation | F64: Edge case | G64: Non-violation(im not sure!) | H64: Non-violation | I64: Non-violation | J64: Freya: I think this one and the shower one both decribe the experience and not just describe it like "the shower is good"or "the maker is good"
A65: R084 | B65: 85 | C65: I do the cooking and my husband washes the dishes. We are both loving our new Caraway Cookware! | D65: https://www.target.com/p/-/A-84074803? | E65: Violation | F65: Clear yes | G65: Violation | H65: Violation | I65: Violation | J65: Miranda: no meaningful description?
A66: R085 | B66: 86 | C66: Bought the L for my 60lb pitty. He fit the ears but they were almost too small, it’s that darn blocky head (and him pushing his ears back all the time). But don’t size up because otherwise the body would have been too big! | D66: target website | E66: Non-violation | F66: Clear no | G66: Non-violation | H66: Non-violation | I66: Non-violation
...

Sheet Test
A1: ID | B1: Original Row | C1: Review | D1: Source | E1: Label | F1: Level of Difficulty | G1: Miranda's Label | H1: Chris's Label | I1: Freya's Label | J1: Notes on Disagreements | K1: Original Extra Annotation
A2: R007 | B2: 8 | C2: “This is my go to perfume it last long and smells even better. ALL I CAN SAY IS WOW” | D2: Amazon-Reviews-2023 dataset all_beauty | E2: Non-violation | F2: Clear no | G2: Non-violation | H2: Non-violation | I2: Non-violation | J2: \
A3: R009 | B3: 10 | C3: “I bought one for myself and one for my granddaughter” | D3: Amazon-Reviews-2023 dataset Handmade_products | E3: Violation | F3: Edge case | G3: Non-violation | H3: Violation (doesn't talk about the product) | I3: Violation | J3: Miranda: just simply describing the usage of the product with a rate? not violating our policy cuz it's not fake Freya: Maybe it is a useless review that can be conceal? Chris: No mention of the product; only that a purchase was made.
A4: R011 | B4: 12 | C4: "I ordered the clear one by mistake and it was smaller than I expected but it came fast and was packaged very well. I think it's beautiful. I just have to figure out how to hang it because you can't see it that well with the white background." | D4: Amazon-Reviews-2023 dataset Handmade_products | E4: Non-violation | F4: Clear no | G4: Non-violation | H4: Non-violation | I4: Non-violation | J4: \
A5: R014 | B5: 15 | C5: "I have been using them for a week and when I read some of the comments in other reviews I am mystified. I use mine just like a normal Echo View. Stream, play music, get the weather, buy crap from the big A on them. No problems. The basic difference in functionality is the home screen on the Hub has actual persistent buttonology that the View lacks. This is because the OS is skewed toward physical AND verbal interaction with the device. I can swish and the weather is front and center. I can push the four buttons for my Ring system and it will bring up the four most recently viewed cameras as a set, which is very visible. Or I can select one view and it will fill the screen with that camera image. I can answer the front door or say hello to my wife in the driveway through the hub..." | D5: https://www.amazon.com/dp/B0BCR7M9KX?ref_=nav_em__ods_ha_echo_go_0_2_4_4&th=1 | E5: Non-violation | F5: Clear no | G5: Non-violation | H5: Non-violation | I5: Non-violation | J5: \
A6: R022 | B6: 23 | C6: I cannot stress enough how essential this Castor Oil is—it’s truly a must-have in your home, your car, and even your purse! I’ve had the pleasure of using this product daily, and I genuinely can’t live without it. It’s one of the most versatile and powerful natural oils I’ve ever used. Whether I’m using it as a moisturizing lip gloss, a nourishing face or hand oil, or even to help my perfume last longer, it never disappoints. I also rely on it for lymphatic drainage massages, which have helped me keep my tummy flat and feeling amazing. This oil has become an everyday ritual in my self-care routine. If you're looking to enhance your skincare, body care, and overall wellness, I highly recommend you try this product—you’ll see the difference instantly. :sparkles: Use my code Queen Profit at checkout for 15% off your order! Trust me—you won’t want to go a day without it! | D6: https://www.target.com/p/-/A-91835042(Jasmine C.) | E6: Violation | F6: Clear yes | G6: Violation | H6: Violation | I6: Violation | J6: \
A7: R024 | B7: 25 | C7: I have a problem with some conditioners where I always have to get a lot of product in order to detangle it. However with this one, I don't have that problem plus the uv repair is a plus! I received this product for free from Topbox Marketing for testing and review purposes. | D7: Spade: https://www.walmart.com/reviews/product/18168857777?page=2 | E7: Non-violation | F7: Clear no | G7: Non-violation(disclosure) | H7: Non-violation | I7: Non-violation | J7: \
A8: R029 | B8: 30 | C8: Sure, here's a more personalized and hands-on review for the new Insta360 camera: --- **Insta360 New Release: My Personal Take** Having tested this great little camera, I can say it's a must-have for content creators. The compact design makes it super easy to carry around, the quality is simply stunning. The stabilization is top-notch, making even my most dynamic shots smooth and professional. The AI-powered editing tools are a game-changer, saving me tons of time. Whether I'm capturing a special event or just my daily adventures, this camera has become an essential part of my gear. Highly recommend giving it a try! | D8: Chris: https://www.bestbuy.com/product/insta360-go-3s-128gb-action-camera-black/J39VLTZ4XR/sku/11863946/reviews?page=3 | E8: Violation | F8: Clear yes | G8: Violation(this example is so goood,how did you find that?!) | H8: Violation | I8: Violation | J8: \
A9: R032 | B9: 33 | C9: simplyFUEL provided this product for me to try in exchange for an honest review. These are tasty and convenient and my whole family loved them! They are a bit pricey for what they are | D9: Lisa: https://www.walmart.com/reviews/product/14757968534 | E9: Non-violation | F9: Clear no | G9: Non-violation | H9: Non-violation | I9: Non-violation | J9: Undisclosed incentives
A10: R034 | B10: 35 | C10: Came with no memory card but came with a piece of paper offering to give a free card in exchange for a positive review. Complete bull crap and a waste of time | D10: Erica: https://www.walmart.com/reviews/product/14065270343 | E10: Non-violation | F10: Clear no | G10: Non-violation | H10: Non-violation | I10: Non-violation | J10: Undisclosed incentives
A11: R039 | B11: 40 | C11: I believe in probiotics and was shopping for a good one. No side effects so far so I'll continue. | D11: Yuling: https://www.walmart.com/reviews/product/123335924?page=4 | E11: Non-violation | F11: Clear no | G11: Non-violation | H11: Non-violation | I11: Non-violation | J11: Fabricated experience:
A12: R046 | B12: 47 | C12: This really truly works!!!!!!!!! Wrinkles GONE!!!!!!!!! My husband has been mistaken for my father!!!!!!! And he is 8 years younger!!!!!! | D12: Happygranny: https://www.walmart.com/reviews/product/148380420 | E12: Violation | F12: Clear yes | G12: Violation | H12: Violation | I12: Violation
A13: R054 | B13: 55 | C13: Keep in mind that these are being sold individually, not as a set of four. You only get one of the four turtles and it is random. You can buy the whole set for cheaper on Amazon and be guaranteed to get all four. | D13: Dakota: https://www.walmart.com/reviews/product/863633533 | E13: Violation | F13: Edge case | G13: Violation | H13: Non-violation | I13: Violation
A14: R059 | B14: 60 | C14: I LOVE ECOFLOW Ecoflow products!! #1 Solar in Portable Solar Power!! | D14: https://www.ebay.com/itm/146744622946?_trkparms=amclksrc%3DITM%26aid%3D777008%26algo%3DPERSONAL.TOPIC%26ao%3D1%26asc%3D20250416182756%26meid%3D5c5bb914c5ec4a7d98231785fb4c04d6%26pid%3D102690%26rk%3D15%26rkt%3D15%26itm%3D146744622946%26pmt%3D0%26noa%3D1%26pg%3D4375194%26algv%3DFeaturedDealsV2%26tu%3D01M5R3DVR3EPS8CG2E661PQT0B | E14: Violation | F14: Clear yes | G14: Violation | H14: Violation | I14: Violation
A15: R064 | B15: 65 | C15: This Miffy plush is sooo big and comfy!! perfect addition to my bedding. Im so happy! | D15: https://www.target.com/p/kids-39-28-34-x22-34-faux-fur-reversible-miffy-xl-plush-miffy-by-pillowfort-8482/-/A-95161499 | E15: Non-violation | F15: Edge case | G15: Non-violation(not sure whether we should consider it as with detail or not) | H15: Non-violation | I15: Non-violation
A16: R065 | B16: 66 | C16: My son loves it | D16: https://www.target.com/p/bluey-airblown-inflatable-bluey-in-vampire-costume-bluey-3-5-ft-tall-blue/-/A-89003106#lnk=sametab | E16: Violation | F16: Clear yes | G16: Violation | H16: Violation | I16: Violation
A17: R068 | B17: 69 | C17: I loved everything about it except for the olives—that’s a personal thing. The variety is lovely just like the presentation. once i got a hold of the platter i ate everything | D17: https://www.target.com/p/fight-or-flight-target-exclusive-by-jeff-kinney-hardcover/-/A-1011973222?content_id=STORY-48015 | E17: Non-violation | F17: Clear no | G17: Non-violation | H17: Non-violation | I17: Non-violation
A18: R070 | B18: 71 | C18: [This review was collected as part of a promotion.] This book is engaging and fun for elementary school kids. It is colorful and age appropriate. The mazes are super fun. The book even comes with a page of Halloween stickers! The Ghoulie Game was a delight. It was also nice to see a color by number included in this book as well. The matching game also added some variety to the activities inside the book. | D18: https://www.target.com/p/fight-or-flight-target-exclusive-by-jeff-kinney-hardcover/-/A-1011973222?content_id=STORY-48015 | E18: Non-violation | F18: Edge case | G18: Non-violation | H18: Non-violation | I18: Non-violation
A19: R075 | B19: 76 | C19: Order delivered on time with no issues | D19: https://www.ebay.com/fdbk/mweb_profile?fdbkType=FeedbackReceivedAsSeller&item_id=840014598655&username=bullseye_deals&filter=feedback_page%3ARECEIVED_AS_SELLER&q=840014598655&sort=RELEVANCEV2 | E19: Violation | F19: Clear yes | G19: Violation | H19: Violation | I19: Violation
A20: R079 | B20: 80 | C20: Great water flow. Bought a second one also. | D20: Amazon.com: INAVAMZ 2 in 1 Shower Head with Handheld Combo High Pressure Silver 1.8 GPM | 7.2" Rain Showerhead and 10 Spray Hand Held Shower, Adjustable Shower Angle, 59-inch Rotatable Stainless Steel Hose | E20: Non-violation | F20: Edge case | G20: Non-violation(a bit decription of the water flow??) | H20: Non-violation | I20: Non-violation
A21: R080 | B21: 81 | C21: Best grinder value. A must have. | D21: https://www.amazon.com/portal/customer-reviews/B074H6K5F1/ref=cm_cr_unknown?ie=UTF8&filterByStar=five_star&reviewerType=all_reviews#reviews-filter-bar | E21: Violation | F21: Clear yes | G21: Violation | H21: Violation | I21: Violation
A22: R100 | B22: 101 | C22: Love these bottles, great quality Right out of the box, I noticed how premium it felt. It’s lightweight but super sturdy, and I love that it gives a clean, glass-like look. Honestly, it feels like this bottle was made by someone who gets what both babies and parents need. | D22: https://www.target.com/p/quark-buubibottle-max-gift-set-gray-2pk-8-fl-oz/-/A-94568992#lnk=sametab | E22: Non-violation | F22: Clear no | G22: Non-violation | H22: Non-violation | I22: Non-violation
